model
name = 0jo9ru72vqb0uq5j
size = 8 25 7
scale = 0.05
origin = -y
shell = Outline 0.25
material type = toon, lighting = smooth, deform = 1 1
  colors = A:#1D1D11 B:#F2D9A9
material type = basic, lighting = smooth, roughness = 0, refractionRatio = 1, side = back
  colors = Outline:#000
voxels
-------- -------- -------- -------- -------- A------- A------- -------- -------- -------- -------- -------- -------- -------- -------- -------- -------- -------- -------- A------- -------- -------- -------- -------- -------- 
-------- -------- -------- -------- -------- -------- A------- -------- -------- -------- ----AAA- -------- -------- -------- -------- -------- -------- -------- A------- A------- -------- A------- A------- -------- -------- 
-------- A------- -------- -------- A------- A------- -------- -------- -------- A---AAA- A--AAAAA A---BBB- ----BBB- ----BBB- ----BBB- ----BBB- -------- A------- A------- -------- A------- -------- -------- A------- -------- 
A------- A------- A------- A------- A------- AAAAA--- AA--AA-- A----A-- A----A-- A---AAA- A--AAAAA A---BBB- A---BBB- A---BBB- A---BBB- A---BBB- A------- A------- A------- A------- -------- -------- -------- -------- A------- 
-------- A------- -------- -------- A------- A------- -------- -------- -------- A---AAA- A--AAAAA A---BBB- ----BBB- ----BBB- ----BBB- ----BBB- -------- A------- A------- -------- A------- -------- -------- A------- -------- 
-------- -------- -------- -------- -------- -------- A------- -------- -------- -------- ----AAA- -------- -------- -------- -------- -------- -------- -------- A------- A------- -------- A------- A------- -------- -------- 
-------- -------- -------- -------- -------- A------- A------- -------- -------- -------- -------- -------- -------- -------- -------- -------- -------- -------- -------- A------- -------- -------- -------- -------- -------- 
