model
name = 21t8q9otkok01bdr
size = 22 27 3
scale = 0.05
origin = -y
shell = Outline 0.25
material type = toon, lighting = smooth, deform = 1 1
  colors = A:#01FE01 B:#5A2C20 C:#6D3011 D:#B17500 E:#FE01FE
material type = basic, lighting = smooth, roughness = 0, refractionRatio = 1, side = back
  colors = Outline:#000
voxels
---------------------- ---------------------- ---------------------- ---------------------- ---------------------- ---------------------- ---------------------- ---------------------- ---------------------- ---------------------- ---------------------- ---------------------- ---------------------D ---------------------D ---------------------D ---------------------D ---------------------- ---------------------- ---------------------- ---------------------- ---------------------- ---------------------- ---------------------- ---------------------- ---------------------- ---------------------- ---------------------- 
E-----------BBBBBBBBB- -----------BAAACACAAAB -----------BAACAAACAAB -----------BACAAAAACAB -----------BACAAAAACAB -----------BCAAAAAAACB -----------BCAAAAAAACB -----------BACAAAAACAB -----------BACAAAAACAB -----------BAACACACAAB -----------BAAACACAAAB -----------BAACAAACAAB -----------BACAAAAACAB -----------BCAAAAAAACB -----------BACAAAAACAB -----------BAACAAACAAB -----------BAAACACAAAB -----------BAACACACAAB -----------BACAAAAACAB -----------BACAAAAACAB -----------BCAAAAAAACB -----------BCAAAAAAACB -----------BACAAAAACAB -----------BACAAAAACAB -----------BAACAAACAAB -----------BAAACACAAAB ------------BBBBBBBBB- 
E--------------------- ---------------------- ---------------------- ---------------------- ---------------------- -----------D---------- -----------D---------- -----------D---------- -----------D---------- ---------------------- ---------------------- ---------------------- ---------------------- ---------------------- ---------------------- ---------------------- ---------------------- -----------D---------- -----------D---------- -----------D---------- -----------D---------- ---------------------- ---------------------- ---------------------- ---------------------- ---------------------- ---------------------- 
