model
name = 2qivn3hq1zz0ks6b
size = 30 38 9
scale = 0.05
origin = -y
shell = Outline 0.25
material type = toon, lighting = smooth, deform = 1 1
  colors = A:#2E3A22 B:#C8A44D C:#222B11 D:#BA953B E:#1C2211 F:#B17500 G:#FE01FE
material type = basic, lighting = smooth, roughness = 0, refractionRatio = 1, side = back
  colors = Outline:#000
voxels
4(26A-2A-)2(26A-3E)15(26A-2A-)3A20-3A-2A-3A-18F8(-3A-2A-3A-F16EF)-3A-2A-3A-18F-3A-3E3A20-3A-3E5(26A-2A-)4(26AC2A-)2(26A4E)15(26AC2A-)10(3A20C3AC2A-)2(3A20C3A4E)2(26AC2A-)6A2-18A2(C2A-26A)C2A29-A2-25B2FA2-27B2(A2-2B24-B)2(2E-2B24-B)2(A2-2B24-B)21(C2-2B24-B)2(A2-2B24-B)2(2E-2B24-B)2(A2-2B24-B)A2-25B2F2(A29-)A2-26DFA2-25D2B2(A2-2D24-B)AE-2D22-G-BAE-2(2D24-BA2-)21(2D24-BC2-)2(2D24-BA2-)2(2D24-BAE-)2D24-BA2-2D3-G20-BA2-2D24-BA2-26DF2(A29-)A2-26BFA2-27B2(A2-2B24-B)2(AE-2B24-B)2(A2-2B24-B)21(C2-2B24-B)2(A2-2B24-B)2(AE-2B24-B)2(A2-2B24-B)A2-26BF2(A29-)A2-26DFA2-25D2B2(A2-2D24-B)2(AE-2D24-B)2(A2-2D24-B)21(C2-2D24-B)2(A2-2D24-B)2(AE-2D24-B)2(A2-2D24-B)A2-26DF2(A29-)A2-25B2FA2-27B2(A2-2B24-B)2(AE-2B24-B)2(A2-2B24-B)21(C2-2B24-B)2(A2-2B24-B)2(AE-2B24-B)2(A2-2B24-B)A2-25B2FA29-A4(-26AC2A)-2(26A4E)25(26AC2A-)2(26A4E)5(26AC2A-)4(26A-2A-)2(26A-3E)25(26A-2A-)2(26A-3E)5(26A-2A-)
