model
name = 52s4txnv4vkm261b
size = 9 3 9
scale = 0.05
origin = -y
shell = Outline 0.25
material type = toon, lighting = smooth, deform = 1 1
  colors = A:#3F1C13 B:#B17500 C:#FE01FE
material type = basic, lighting = smooth, roughness = 0, refractionRatio = 1, side = back
  colors = Outline:#000
voxels
--AAAAA-- --------- --------- 
-AAAAAAA- --BBBBB-- --CCCCC-- 
AAAAAAAAA -BBBBBBB- -CCCCCCC- 
AAAAAAAAA -BBBBBBB- -CCCCCCC- 
AAAAAAAAA -BBBBBBB- -CCCCCCC- 
AAAAAAAAA -BBBBBBB- -CCCCCCC- 
AAAAAAAAA -BBBBBBB- -CCCCCCC- 
-AAAAAAA- --BBBBB-- --CCCCC-- 
--AAAAA-- --------- --------- 
