model
name = 6k5rnoul03wux1r0
revision = 36
size = 14 26 12
scale = 0.05
origin = -y
shell = Outline 0.25
material type = toon, lighting = smooth, deform = 1 1
  colors = A:#3F1C13 B:#781B11
material type = basic, lighting = smooth, roughness = 0, refractionRatio = 1, side = back
  colors = Outline:#000
voxels
-------------- -A----------A- -A----------A- -A----------A- -A----------A- -A----------A- -A----------A- -A----------A- -AA--------AA- -AAA------AAA- -AAAAAAAAAAAA- -AAAAAAAAAAAA- -A----AA----A- -A----AA----A- -A----AA----A- -A----AA----A- -A----AA----A- -A----AA----A- -A---AAAA---A- -A---AAAA---A- -A---AAAA---A- -A---AAAA---A- -A---AAAA---A- -A---AAAA---A- -AAAAAAAAAAAA- -AAAAAAAAAAAA- 
-A------------ -A----------A- -A----------A- -A----------A- -A----------A- -A----------A- -A----------A- -AA--------AA- -AAA------AAA- -AAAAAAAAAAAA- -AAAAAAAAAAAA- -------------- -------------- -------------- -------------- -------------- -------------- -------------- -------------- -------------- -------------- -------------- -------------- -------------- -------------- -------------- 
A------------A A------------A A------------A A------------A A------------A A------------A A------------A A------------A A------------A AAAAAAAAAAAAAA AAAAAAAAAAAAAA ---BBBBBBBB--- -------------- -------------- -------------- -------------- -------------- -------------- -------------- -------------- -------------- -------------- -------------- -------------- -------------- -------------- 
-------------- -------------- -------------- -------------- -------------- -------------- -------------- A------------A A------------A AAAAAAAAAAAAAA AAAAAAAAAAAAAA --BBBBBBBBBB-- -------------- -------------- -------------- -------------- -------------- -------------- -------------- -------------- -------------- -------------- -------------- -------------- -------------- -------------- 
-------------- -------------- -------------- -------------- -------------- -------------- -------------- -------------- A------------A AAAAAAAAAAAAAA AAAAAAAAAAAAAA --BBBBBBBBBB-- -------------- -------------- -------------- -------------- -------------- -------------- -------------- -------------- -------------- -------------- -------------- -------------- -------------- -------------- 
-------------- -------------- -------------- -------------- -------------- -------------- -------------- -------------- -------------- AAAAAAAAAAAAAA AAAAAAAAAAAAAA --BBBBBBBBBB-- -------------- -------------- -------------- -------------- -------------- -------------- -------------- -------------- -------------- -------------- -------------- -------------- -------------- -------------- 
-------------- -------------- -------------- -------------- -------------- -------------- -------------- -------------- -------------- AAAAAAAAAAAAAA AAAAAAAAAAAAAA --BBBBBBBBBB-- -------------- -------------- -------------- -------------- -------------- -------------- -------------- -------------- -------------- -------------- -------------- -------------- -------------- -------------- 
-------------- -------------- -------------- -------------- -------------- -------------- -------------- -------------- -------------- AAAAAAAAAAAAAA AAAAAAAAAAAAAA --BBBBBBBBBB-- -------------- -------------- -------------- -------------- -------------- -------------- -------------- -------------- -------------- -------------- -------------- -------------- -------------- -------------- 
-------------- -------------- -------------- -------------- -------------- -------------- -------------- -------------- -------------- AAAAAAAAAAAAAA AAAAAAAAAAAAAA --BBBBBBBBBB-- -------------- -------------- -------------- -------------- -------------- -------------- -------------- -------------- -------------- -------------- -------------- -------------- -------------- -------------- 
-------------- -------------- -------------- -------------- -------------- -------------- -------------- -------------- A------------A AAAAAAAAAAAAAA AAAAAAAAAAAAAA --BBBBBBBBBB-- -------------- -------------- -------------- -------------- -------------- -------------- -------------- -------------- -------------- -------------- -------------- -------------- -------------- -------------- 
-------------- -------------- -------------- -------------- -------------- -------------- -------------- A------------A A------------A AAAAAAAAAAAAAA AAAAAAAAAAAAAA ---BBBBBBBB--- -------------- -------------- -------------- -------------- -------------- -------------- -------------- -------------- -------------- -------------- -------------- -------------- -------------- -------------- 
A------------A A------------A A------------A A------------A A------------A A------------A A------------A A------------A A------------A AAAAAAAAAAAAAA AAAAAAAAAAAAAA -------------- -------------- -------------- -------------- -------------- -------------- -------------- -------------- -------------- -------------- -------------- -------------- -------------- -------------- -------------- 
