model
name = 6y70000allmw0jnm
revision = 1
size = 15 52 9
scale = 0.05
origin = -y
shell = Outline 0.25
material type = toon, lighting = smooth, deform = 1 1
  colors = A:#3F1C13 B:#6D3011 C:#985433 D:#5A2C20 E:#522711 G:#824E08 F:#975E12 H:#B17500 I:#484840 J:#383832
material type = basic, lighting = smooth, roughness = 0, refractionRatio = 1, side = back
  colors = Outline:#000
voxels
2D11-2D3C9-4CHC9-CH3C11-4C11-17C15-15C435-15A15C195-2D11-2D3C9-3CH12BDHC12B3C12B17C-13A-15C-C11BC2-C2BG5-G2BC2-CBF7-F23(BC2-CB9-)BC2-CBF7-FBC2-C2BG5-G2BC2-C11BC-15A15C-H11-H9(2-F11-F)2-H11-H-15A15C15-3C9-4CB11ABC-13B2-13B-15C-13A-3C9A3C-28(DA9-AE2-)DA9-BE-15A15C151-F11-F-15AC13BC31-B11AB2(2-13B)-15C-13A-3C9A3C-28(DA9-AE2-)DA9-AE-3A9-3A3C9-3C2-9(B9-B4-)B9-B3-F11BF-15AC13BC31-B11AB2(2-13B)-15C-13A-3C9A3C-14(DA9-AE2-)2(DA-2G6-AE2-)2(DA-2G3-2G-AE2-)DA-GF3-GF-AE2-DA-2G3-2G2(-AE2-DA-GF3-GF)-AE2-DA-2F3-2(GF-AE2-DA6-)2F-4(AE2-DA9-)AE-3A9-3A3C9-3C2-9(B9-B4-)B9-B3-F11BF-15AC13BC31-B11AB2(2-13B)-15C-13A-3C9A3C-14(DA9-AE2-)2(DA-2G6-AE2-)7(DA-2G3-2G-AE2-)DA2-I3-2G-AE2-DA2-J3-2G-2(AE2-DA2-I3-I2-AE2-DA2-J3-J2-)AE-3A9-3A3C9-3C2-9(B9-B4-)B9-B3-F11BF-15AC13BC15-3C9-4CB11ABC-13B2-13B-15C-13A-3C9A3C-28(DA9-AE2-)DA9-AE-3A9-3A3C9-3C2-9(B9-B4-)B9-B3-F11BF-15AC13BC2D11-2D3C9-3CHB11ABHC13B2C13B16C-13A-15C-28(D11AE2-)2D10AE-3A9-3A3C9-3C2-9(B9-B4-)B9-B3-F11BF-15AC13BC2D11-2D3C9-4C2(9B4-2C)9B4-11C4-C-9A5-10C4-C-17(C8D6-)11(C11DC2-)C11DC-15A15C-H11BH9(2-F11BF)2-H11BH-15A15C
