model
name = 8thfu0s7r5h27pw7
size = 45 20 13
scale = 0.05
origin = -y
shell = Outline 0.25
material type = toon, lighting = smooth, deform = 1 1
  colors = A:#5A2C20 B:#3F1C13 C:#7B3E1E D:#785944
material type = basic, lighting = smooth, roughness = 0, refractionRatio = 1, side = back
  colors = Outline:#000
voxels
2C41-5C39-6C39-7C37-4C-C41AC3-12(41A4-)41A2-44C-44B-2C41-5C39-6C39-7C37-4C-C41AC5(2-13A17-A10-2A)2-2A10-A17-A10-2A2-13A17-13A5(2-2A10-A17-A10-2A)2-43A-44C-44B46-3C39-6C39-7C37-4C-C41AC6(2-2A10-A17-A10-2A5(2-BA10-A17-A10-AB)2-B12A17-12A5(B2-BA10-A17-A10-A)B2-43A-44C-44B182-43A)2-2A10-A17-A10-2A5(2-BA10-A17-A10-AB)2-B12A17-12A5(B2-BA10-A17-A10-A)B2-43A-44C-44B46-3C39-6C39-7C37-4C-C41AC2-2A10-A17-A10-2A5(2-BA10-A17-A10-AB)2-B12A17-12A5(B2-BA10-A17-A10-A)B2-43A-44C-44B-2C41-5C39-6C39-7C37-4C-2C40AC6(2-2A10-A17-A10-2A)2-13A17-13A5(2-2A10-A17-A10-2A)2-43A-44C-44B-2C41-5C39-6C16-7A16-7C2-6A4-13A4-6A2-4C-C15A5-A5-15AC3-3(A10-2(A8-)A10-A4-)A10-AD7-A7-D2(A10-A4-A10-2(A8-))A10-A4-12A8-A8-12A2(4-A10-2(A8-)A10-A)4-A10-AD7-A7-D2(A10-A4-A10-2(A8-))A10-A4-41A2-44C-44B811-44C-44B-
