model
name = 9p3o9erb00wtens0
size = 9 3 9
scale = 0.05
origin = -y
shell = Outline 0.25
material type = toon, lighting = smooth, deform = 1 1
  colors = A:#222B11 B:#B17500 C:#FE01FE
material type = basic, lighting = smooth, roughness = 0, refractionRatio = 1, side = back
  colors = Outline:#000
voxels
--AAAAA-- --------- --------- 
-AAAAAAA- --BBBBB-- --CCCCC-- 
AAAAAAAAA -BBBBBBB- -CCCCCCC- 
AAAAAAAAA -BBBBBBB- -CCCCCCC- 
AAAAAAAAA -BBBBBBB- -CCCCCCC- 
AAAAAAAAA -BBBBBBB- -CCCCCCC- 
AAAAAAAAA -BBBBBBB- -CCCCCCC- 
-AAAAAAA- --BBBBB-- --CCCCC-- 
--AAAAA-- --------- --------- 
