model
name = 9t4p89oxjljdopsm
size = 16 14 16
scale = 0.05
origin = -y
shell = Outline 0.25
material type = toon, lighting = smooth, deform = 1 1
  colors = A:#3F1C13 B:#5A2C20
material type = basic, lighting = smooth, roughness = 0, refractionRatio = 1, side = back
  colors = Outline:#000
voxels
-BBBBBBBBBBBBBBB ---------------- ---------------- ---------------- ---------------- ---------------- ---------------- ---------------- ---------------- ---------------- ---------------- ---------------- ---------------- ---------------- 
---------------- ---------------- ---------------- ---------------- ---------------- ---------------- ---------------- ---------------- ---------------- ---------------- ---------------- ---------------- ---------------- BBBBBBBBBBBBBBBB 
-AA----------AA- -AA----------AA- -AA----------AA- -AA----------AA- -AA----------AA- -AA----------AA- -AA----------AA- -AA----------AA- -AA----------AA- -AA----------AA- -AA----------AA- -AA----------AA- -AA----------AA- BBBBBBBBBBBBBBBB 
-AA----------AA- -AA----------AA- -AA----------AA- -AA----------AA- -AA----------AA- -AA----------AA- -AA----------AA- -AA----------AA- -AA----------AA- -AA----------AA- -AAAAAAAAAAAAAA- -AAAAAAAAAAAAAA- -AAAAAAAAAAAAAA- BBBBBBBBBBBBBBBB 
---------------- ---------------- ---------------- ---------------- ---------------- ---------------- ---------------- ---------------- ---------------- ---------------- --A----------A-- --A----------A-- --A----------A-- BBBBBBBBBBBBBBBB 
---------------- ---------------- ---------------- ---------------- ---------------- ---------------- ---------------- ---------------- ---------------- ---------------- --A----------A-- --A----------A-- --A----------A-- BBBBBBBBBBBBBBBB 
---------------- ---------------- ---------------- ---------------- ---------------- ---------------- ---------------- ---------------- ---------------- ---------------- --A----------A-- --A----------A-- --A----------A-- BBBBBBBBBBBBBBBB 
---------------- ---------------- ---------------- ---------------- ---------------- ---------------- ---------------- ---------------- ---------------- ---------------- --A----------A-- --A----------A-- --A----------A-- BBBBBBBBBBBBBBBB 
---------------- ---------------- ---------------- ---------------- ---------------- ---------------- ---------------- ---------------- ---------------- ---------------- --A----------A-- --A----------A-- --A----------A-- BBBBBBBBBBBBBBBB 
---------------- ---------------- ---------------- ---------------- ---------------- ---------------- ---------------- ---------------- ---------------- ---------------- --A----------A-- --A----------A-- --A----------A-- BBBBBBBBBBBBBBBB 
---------------- ---------------- ---------------- ---------------- ---------------- ---------------- ---------------- ---------------- ---------------- ---------------- --A----------A-- --A----------A-- --A----------A-- BBBBBBBBBBBBBBBB 
---------------- ---------------- ---------------- ---------------- ---------------- ---------------- ---------------- ---------------- ---------------- ---------------- --A----------A-- --A----------A-- --A----------A-- BBBBBBBBBBBBBBBB 
---------------- ---------------- ---------------- ---------------- ---------------- ---------------- ---------------- ---------------- ---------------- ---------------- --A----------A-- --A----------A-- --A----------A-- BBBBBBBBBBBBBBBB 
---------------- ---------------- ---------------- ---------------- ---------------- ---------------- ---------------- ---------------- ---------------- ---------------- --A----------A-- --A----------A-- --A----------A-- BBBBBBBBBBBBBBBB 
-AA----------AA- -AA----------AA- -AA----------AA- -AA----------AA- -AA----------AA- -AA----------AA- -AA----------AA- -AA----------AA- -AA----------AA- -AA----------AA- -AAAAAAAAAAAAAA- -AAAAAAAAAAAAAA- -AAAAAAAAAAAAAA- BBBBBBBBBBBBBBBB 
-AA----------AA- -AA----------AA- -AA----------AA- -AA----------AA- -AA----------AA- -AA----------AA- -AA----------AA- -AA----------AA- -AA----------AA- -AA----------AA- -AA----------AA- -AA----------AA- -AA----------AA- BBBBBBBBBBBBBBBB 
