model
name = b6ivt13r47fvew13
size = 7 9 3
scale = 0.05
origin = -y
shell = Outline 0.25
material type = toon, lighting = smooth, deform = 1 1
  colors = A:#5A2C20 B:#C8A44D C:#4D2211 D:#B17500 E:#3F1C13
material type = basic, lighting = smooth, roughness = 0, refractionRatio = 1, side = back
  colors = Outline:#000
voxels
AAAAACA AAAAACA AAAAACE AAAAACA AAAAACA ADDDDCA ADDDDCE AAAAACA AAAAACA 
-BBBBDA -BBBBBA -BBBBBE -BBBBBA -BBBBBA -BBBBBA -BBBBBE -BBBBBA -BBBBDA 
AAAAACA AAAAACA AAAAACE AAAAACA AAAAACA AAAAACA AAAAACE AAAAACA AAAAACA 
