model
name = dtwq3iibc7498tvr
revision = 1
size = 21 29 13
scale = 0.05
origin = -y
shell = Outline 0.25
material type = toon, lighting = smooth, deform = 1 1
  colors = A:#5A2C20 B:#3F1C13 C:#260F00 D:#985433 E:#006D5A G:#424753 F:#B17500 H:#7B3E11 I:#C8A44D J:#1F212A K:#17BE6E
material type = basic, lighting = smooth, roughness = 0, refractionRatio = 1, side = back
  colors = Outline:#000
voxels
--------------------- --------------------- --------------------- --------------------- --------------------- --------------------- --------------------- --------------------- --------------------- --------------------- --------------------- --------------------- --------------------- --------------------- --------------------- --------------------- --------------------- --------------------- --------------------- --------------------- --------------------- --------------------- --------------------- --------------------- --------------------- --------------------- -AA---------------AA- BBBBBBBBBBBBBBBBBBBBB CCCCCCCCCCCCCCCCCCCCC 
--------------------- --------------------- --------------------- --------------------- --------------------- --------------------- --------------------- --------------------- --------------------- --------------------- --------------------- --------------------- --------------------- --------------------- --------------------- --------------------- --------------------- --------------------- --------------------- --------------------- --------------------- -AA---------------AA- -AA---------------AA- -AA---------------AA- -AA---------------AA- -AA---------------AA- -AA---------------AA- BAAAAAAAAAAAAAAAAAAAB CCCCCCCCCCCCCCCCCCCCC 
-AAA-------------AAA- -AAAAAAAAAAAAAAAAAAA- -AAAAAAAAAAAAAAAAAAA- -CCCCCCCCCCCCCCCCCCC- -AA---------------AA- -AA---------------AA- -AA---------------AA- -AA---------------AA- -AA---------------AA- -AA---------------AA- -AA---------------AA- -AA---------------AA- -AA---------------AA- -AA---------------AA- -AA---------------AA- -AA---------------AA- -AA---------------AA- -AA---------------AA- -AA---------------AA- -AA---------------AA- -AA---------------AA- -AA---------------AA- -AA---------------AA- -AA---------------AA- -AA---------------AA- -AABBBBBBBBBBBBBBBAA- -AABBBBBBBBBBBBBBBAA- BAAAAAAAAAAAAAAAAAAAB CCCCCCCCCCCCCCCCCCCCC 
-AAA-------------AAA- -ADDDDDDDDDDDDDDDDDA- -AHHHHHHHHHHHHHHHHHA- -CBAAAAAAAAAAAAAAABC- -AB---------------BA- -AB---------------BA- -AB---------------BA- -AB---------------BA- -AB---------------BA- -AB---------------BA- -AB-GGGGGGGG------BA- -AB-IIIIIIII------BA- -AB-GGGGGGGG------BA- -AB---------------BA- -ABAAAAAAAAAAAAAAABA- -AB---------------BA- -AB---------------BA- -AB---------------BA- -AB---------------BA- -AB---------------BA- -AB---------------BA- -AB---------------AA- -AB---------------AA- -AB---------------AA- -AB---------------AA- -AABBBBBBBBBBBBBBBAA- -AABBBBBBBBBBBBBBBAA- BAAAAAAAAAAAAAAAAAAAB CCCCCCCCCCCCCCCCCCCCC 
-AAA-------------AAA- -ADDDDDDDDDDDDDDDDDA- -AHHHHHHHHHHHHHHHHHA- -CBAAAAAAAAAAAAAAABC- --B-EEEEEEEE------B-- --B-IIIIIIII------B-- --B-EEEEEEEE------B-- --BDDDDDDDD-------B-- --BIIIIIIII-------B-- --BDDDDDDDD-------B-- --B-GGGGGGGG------B-- --B-IIIIIIII------B-- --B-GGGGGJJG------B-- --B---------------B-- --BAAAAAAAAAAAAAAAB-- --B---------------B-- --B---------------B-- --B---------------B-- --B---------------B-- --B---------------B-- --B---------------B-- --B---------------B-- --B---------------B-- --B---------------B-- --B---------------B-- -BBBBBBBBBBBBBBBBBBB- -BBBBBBBBBBBBBBBBBBB- BAAAAAAAAAAAAAAAAAAAB CCCCCCCCCCCCCCCCCCCCC 
--------------------- -ADDDDDDDDDDDDDDDDDA- -AHHHHHHHHHHHHHHHHHA- -CBAAAAAAAAAAAAAAABC- --B-EEEEEEEE--FFDDB-- --B-IIIIIIII--FFDDB-- --B-EEEEEEEE--FFDDB-- --BDDDDDDDD---FFDDB-- --BIIIIIIII---FFDDB-- --BDDDDDDDD---FFDDB-- --B-GGGGGGGG--FFDDB-- --B-IIIIIIII----DDB-- --B-GGGGGJJG----DDB-- --B---------------B-- --BAAAAAAAAAAAAAAAB-- --BEEGGFFDD-------B-- --BEEJJFFHH-------B-- --BEEGGFFDD-------B-- --BEEGGFFDD-------B-- --BEEGGIIDD-------B-- --BKKJJIIDD-------B-- --BEEGGIIHH-------B-- --BEEGGFFDD-------B-- --B---------------B-- --B---------------B-- -BBBBBBBBBBBBBBBBBBB- -BBBBBBBBBBBBBBBBBBB- BAAAAAAAAAAAAAAAAAAAB CCCCCCCCCCCCCCCCCCCCC 
--------------------- -ADDDDDDDDDDDDDDDDDA- -AHHHHHHHHHHHHHHHHHA- -CBAAAAAAAAAAAAAAABC- --B-EEEEEEEE--FFDDB-- --B-IIIIIIII--FFDDB-- --B-EEEEEEEE--FFDDB-- --BDDDDDDDD---FFDDB-- --BIIIIIIII---FFDDB-- --BDDDDDDDD---FFDDB-- --B-GGGGGGGG--FFDDB-- --B-IIIIIIII----DDB-- --B-GGGGGJJG----DDB-- --B---------------B-- --BAAAAAAAAAAAAAAAB-- --BEEGGFFDD-------B-- --BEEGGFFDD-------B-- --BEEGGFFDD-------B-- --BEEGGFFDD-------B-- --BEEGGFFDD-------B-- --BEEGGFFDD-------B-- --BEEGGFFDD-------B-- --BEEGGFFDD-------B-- --B---------------B-- --B---------------B-- -BBBBBBBBBBBBBBBBBBB- -BBBBBBBBBBBBBBBBBBB- BAAAAAAAAAAAAAAAAAAAB CCCCCCCCCCCCCCCCCCCCC 
--------------------- -ADDDDDDDDDDDDDDDDDA- -AHHHHHHHHHHHHHHHHHA- -CBAAAAAAAAAAAAAAABC- --B-EEEEEEEE--FFDDB-- --B-IIIIIIII--FFDDB-- --B-EEEEEEEE--FFDDB-- --BDDDDDDDD---FFDDB-- --BIIIIIIII---FFDDB-- --BDDDDDDDD---FFDDB-- --B-GGGGGGGG--FFDDB-- --B-IIIIIIII----DDB-- --B-GGGGGJJG----DDB-- --B---------------B-- --BAAAAAAAAAAAAAAAB-- --BEEGGFFDD-------B-- --BEEGGFFDD-------B-- --BEEGGFFDD-------B-- --BEEGGFFDD---------- --BEEGGFFDD---------- --BEEGGFFDD---------- --BEEGGFFDD---------- --BEEGGFFDD---------- --B------------------ --B------------------ -BBBBBBBBBBBBBBB---B- -BBBBBBBBBBBBBBBBBBB- BAAAAAAAAAAAAAAAAAAAB CCCCCCCCCCCCCCCCCCCCC 
--------------------- -ADDDDDDDDDDDDDDDDDA- -AHHHHHHHHHHHHHHHHHA- -CBAAAAAAAAAAAAAAABC- --B-EEEEEEEE--FFDDB-- --B-IIIIIIII--FFDDB-- --B-EEEEEEEE--FFDDB-- --BDDDDDDDD---FFDDB-- --BIIIIIIII---FFDDB-- --BDDDDDDDD---FFDDB-- --B-GGGGGGGG--FFDDB-- --B-GGGGGGGG----DDB-- --B-GGGGGGGG----DDB-- --B---------------B-- --BAAAAAAAAAAAAAAAB-- --BEEGGFFDD-------B-- --BEEGGFFDD-------B-- --BEEGGFFDD-------B-- --BEEGGFFDD---------- --BEEGGFFDD---------- --BEEGGFFDD---------- --BEEGGFFDD---------- --BEEGGFFDD---------- --B------------------ --B------------------ -BBBBBBBBBBBBBBB---B- -BBBBBBBBBBBBBBBBBBB- BAAAAAAAAAAAAAAAAAAAB CCCCCCCCCCCCCCCCCCCCC 
--------------------- -ADDDDDDDDDDDDDDDDDA- -AHHHHHHHHHHHHHHHHHA- -CBAAAAAAAAAAAAAAABC- --B-EEEEEEEE--FFDDB-- --B-EEEEEEEE--FFDDB-- --B-EEEEEEEE--FFDDB-- --BDDDDDDDD---FFDDB-- --BDDDDDDDD---FFDDB-- --BDDDDDDDD---FFDDB-- --B-----------FFDDB-- --B-------------DDB-- --B-------------DDB-- --B---------------B-- --BAAAAAAAAAAAAAAAB-- --BEEGGFFDD-------B-- --BEEGGFFDD-------B-- --BEEGGFFDD-------B-- --BEEGGFFDD---------- --BEEGGFFDD---------- --BEEGGFFDD---------- --BEEGGFFDD---------- --BEEGGFFDD---------- --B------------------ --B------------------ -BBBBBBBBBBBBBBB---B- -BBBBBBBBBBBBBBBBBBB- BAAAAAAAAAAAAAAAAAAAB CCCCCCCCCCCCCCCCCCCCC 
-AAA-------------AAA- -ADDDDDDDDDDDDDDDDDA- -AHHHHHHHHHHHHHHHHHA- -CBAAAAAAAAAAAAAAABC- --B-----------FFDDB-- --B-----------FFDDB-- --B-----------FFDDB-- --B-----------FFDDB-- --B-----------FFDDB-- --B-----------FFDDB-- --B-----------FFDDB-- --B-------------DDB-- --B-------------DDB-- --B---------------B-- --BAAAAAAAAAAAAAAAB-- --BEEGGFFDD-------B-- --BEEGGFFDD-------B-- --BEEGGFFDD-------B-- --BEEGGFFDD---------- --BEEGGFFDD---------- --BEEGGFFDD---------- --BEEGGFFDD---------- --BEEGGFFDD---------- --B------------------ --B------------------ -BBBBBBBBBBBBBBB---B- -BBBBBBBBBBBBBBBBBBB- BAAAAAAAAAAAAAAAAAAAB CCCCCCCCCCCCCCCCCCCCC 
-AAA-------------AAA- -ADDDDDDDDDDDDDDDDDA- -AHHHHHHHHHHHHHHHHHA- -CBBBBBBBBBBBBBBBBBC- -AB-----------FFDDBA- -AB-----------FFDDBA- -AB-----------FFDDBA- -AB-----------FFDDBA- -AB-----------FFDDBA- -AB-----------FFDDBA- -AB-----------FFDDBA- -AB-------------DDBA- -AB-------------DDBA- -AB---------------BA- -ABAAAAAAAAAAAAAAABA- -ABEEGGFFDD-------BA- -ABEEGGFFDD-------BA- -ABEEGGFFDD-------BA- -ABEEGGFFDD--------A- -ABEEGGFFDD--------A- -ABEEGGFFDD--------A- -ABEEGGFFDD--------A- -ABEEGGFFDD--------A- -AB----------------A- -AB----------------A- -AABBBBBBBBBBBBB---A- -AABBBBBBBBBBBBBBBAA- BAAAAAAAAAAAAAAAAAAAB CCCCCCCCCCCCCCCCCCCCC 
-AAA-------------AAA- -AAAAAAAAAAAAAAAAAAA- -AAAAAAAAAAAAAAAAAAA- -CCCCCCCCCCCCCCCCCCC- -AACCCCCCCCCCCCCCCAA- -AACCCCCCCCCCCCCCCAA- -AACCCCCCCCCCCCCCCAA- -AACCCCCCCCCCCCCCCAA- -AACCCCCCCCCCCCCCCAA- -AACCCCCCCCCCCCCCCAA- -AACCCCCCCCCCCCCCCAA- -AACCCCCCCCCCCCCCCAA- -AACCCCCCCCCCCCCCCAA- -AACCCCCCCCCCCCCCCAA- -AACCCCCCCCCCCCCCCAA- -AACCCCCCCCCCCCCCCAA- -AACCCCCCCCCCCCCCCAA- -AACCCCCCCCCCCCCCCAA- -AACCCCCCCCCCCCC---A- -AACCCCCCCCCCCCC---A- -AACCCCCCCCCCCCC---A- -AACCCCCCCCCCCCC---A- -AACCCCCCCCCCCCC---A- -AACCCCCCCCCCCCC---A- -AACCCCCCCCCCCCC---A- -AABBBBBBBBBBBBB---A- -AABBBBBBBBBBBBBBBAA- BBBBBBBBBBBBBBBBBBBBB CCCCCCCCCCCCCCCCCCCCC 
