model
name = duck
revision = 67
size = 27 36 40
scale = 0.005
origin = -y
shell = Outline 0.25
material type = toon, lighting = smooth, deform = 4 1
  colors = B:#F0B429 E:#E65C1E A:#B14819 C:#FFF D:#0C0C0C G:#191918 F:#82330F
material type = basic, lighting = smooth, roughness = 0, refractionRatio = 1, side = back
  colors = Outline:#000
voxels
739-2E2-3E20-7E21-5E24-E727-3E22-7E20-7A73-3E3-3E18-8E20-7E21-5E24-E727-3E21-8E19-3E3A3E18-E2A3-2A19-2A4-3A18-3E2-4E18-8E20-7E22-3E375-2B25-3B24-2B323-B22-9E18-E-2EA4E17-4EF-F3E17-3EA3-A2E18-9E19-7E21-2EB2E293-2B25-3B23-5B21-7B19-8B19-9B18-8B20-6B22-5B23-3B24-2B238-9E17-2E2-3E-2E17-5EF5E16-4EA-A4E17-9E19-E5BE22-3B266-5B20-8B19-9B17-5B-5B15-5B3-5B13-5B5-5B12-4B6-5B12-5B4-5B14-5B3-5B15-5B-5B17-9B19-7B20-6B23-3B160-B22-3EBEB3E17-3E5-3E15-B11E15-B3EBEAEB3E17-2E-BEB-2E19-3B-3B21-5B24-B213-4B20-11B15-5B3-5B13-4B6-5B12-4B7-4B11-4B9-2(3B11-)3B10-2B12-3B10-2(3B11-)3B9-3B12-4B7-4B12-5B5-5B13-4B4-5B14-6B-5B18-7B156-5B19-3E5B2E17-BE7-EB15-2B-2B3E2B-2B14-6BE2B-3B15-3B5-3B18-2B3-2B21-5B22-4B24-2B160-3B20-10B16-5B2-6B13-3B9-2(3B11-)2B11-2B13-2B10-2B13-2B9-2B14-2B9-2B15-2B8-3B2(13-2B10-2B)13-2B10-3B11-2B12-2B10-3B12-5B5-5B13-12B19-5B77-3B23-5B20-8B18-4B3-4B15-2B8-3B2(14-2B9-2B)14-4B5-4B15-4B3-4B16-4B2-5B17-9B18-8B21-5B128-9B16-6B-5B14-3B8-4B11-3B2(11-2B)13-2B9-2B14-2B9-2B15-2B8-2B15-2B7-2B16-2(2B8-2B15-)2B8-2B14-3B9-2(2B13-2B10-)3B10-3B12-6B3-5B15-10B21-2B25-3B22-7B18-5B-4B17-4B3-4B15-3B6-4B14-2B9-2B13-2B11-B13-2B11-2B13-2B9-2B14-GB9-BG14-G2B7-2BG14-C2B6-3B16-4B3-4B16-11B19-5B100-11B15-3B7-3B12-3B10-3B11-2B13-2B9-2B14-3B8-2B15-2B7-2B16-3B4(6-2B17-2B)6-3B2(15-2B8-2B)14-2B10-2B12-3B11-3B8-4B13-13B16-8B19-8B18-5B-5B15-4B5-3B15-2B8-3B13-3B9-3B4(12-2B11-2B)12-CD11-2C12-CD10-B2C12-CDB9-BC14-2B9-2B14-5B3-4B17-9B20-4B73-13B13-3B9-2(3B11-)3B9-2B14-3B8-2B15-2B7-2B17-2B6-2B17-2B5-3(2B19-2B4-)2B18-3B5-2B17-2B6-2B16-3B7-2B15-2B8-3B13-2B10-3B11-2B12-4B6-4B15-5B-5B16-4B2-5B15-3B6-4B13-3B9-2B13-2B10-2(3B11-)2B11-4(2B13-2B10-)BD13-CB10-BD12-2C12-2B11-2B12-2B10-3B13-3B7-3B15-4B2-5B17-9B21-3B45-14B12-3B11-2B10-3B13-2B9-2B15-2B7-2B17-2B6-2B17-2B5-2B19-2B3-3B19-2B3-2B21-2B2-2B21-2B3-2B19-2B4-2B19-2B5-2B17-2B6-2B16-3B7-2B14-3B9-2B12-3B11-3B9-3B13-3B7-3B14-3B7-3B13-3B9-2B12-3B2(11-2B)12-3B10-2B13-2B9-2B14-2B9-3(2B15-2B8-)2B14-2B10-2B13-2B10-2B12-3B10-3B11-2B12-3B9-3B13-3B7-3B15-5B-4B19-7B42-16B11-2B12-3B9-2B14-3B7-2B16-3B6-2B17-2B5-2B19-2B4-2B19-2B3-2B21-2B2-B22-2(2B2-2B21-)2B3-2B19-2B4-2B19-2B5-2B17-2B6-3B15-2B8-3B13-2B10-3B11-2B12-3B8-3B13-3B9-2B12-3B2(11-2B)12-3B9-2B14-2B9-2(2B15-2B8-)B16-2B7-2B17-B8-B16-2B8-2B15-2B8-2B14-3B8-2B14-2B10-2B13-2B10-3B11-2B12-3B8-3B15-3B5-3B17-9B41-17B9-2B14-3B7-3B15-2B7-2B17-2B5-2B19-B5-2B19-2B3-2B21-B3-2B21-2B2(2-B23-B)2-2B21-2B2-2B21-B4-2B19-2B4-2B18-2B6-2B16-3B7-2B14-3B9-2B12-3B11-3B9-3B12-2B10-3B11-2B12-3B10-B14-2B9-2B15-B9-B16-2B2(8-B17-B)7-2B3(17-B8-B)16-2B8-2B15-B10-B14-2B10-2B12-3B11-3B9-3B13-3B7-3B15-10B22-B17-18B9-2B15-2B7-2B17-2B6-B18-2B5-2B19-2B4-B20-2B3-2B21-2B2-B22-2B2(2-B23-B)2-B22-2B2-2B21-2B3-B20-2B4-2B19-2B5-2B17-2B7-2B15-2B9-2B13-2(2B11-)2B12-2(2B11-)2B13-2B10-B15-B9-2B15-B9-B16-2B2(8-B17-B)7-2B3(17-B8-B)16-2B8-2B15-B10-B15-B10-2B13-2(2B11-)2B13-2B8-3B15-11B19-4B16-18B8-2B16-2B7-2B17-2B5-2B19-B5-2B19-2B3-2B21-B3-2B21-2B2(2-B23-B)-2B23-4B23-2B-2B21-2B2-2B21-2B3-2B19-2B5-2B17-2B7-2B15-2B9-2B13-2(2B11-)2B12-2(2B11-)2B13-2B10-B14-2B9-2B15-B9-B16-2B2(8-B17-B)7-2B3(17-B8-B)16-2B8-2B15-B10-B15-B10-2B13-2(2B11-)2B13-2B9-2B15-4B2-5B19-5B15-18B8-2B16-3B6-B18-2B5-2B19-2B4-B20-2B3-2B21-2B2-B22-2B2(2-B23-B)-2B23-4B23-2B-B23-B2-2B21-2B3-2B19-2B5-2B17-2B7-2B15-2B9-2B13-2(2B11-)2B12-2(2B11-)2B13-B11-B14-2B9-2B15-B9-B16-2B2(8-B17-B)7-2B3(17-B8-B)16-2B8-2B15-B10-B15-B10-2B13-2(2B11-)2B13-2B9-2B15-4B2-5B19-5B15-18B8-2B16-3B5-2B19-B5-2B19-2B3-2B21-B3-2B21-2B2(2-B23-B)2-B3(23-4B)23-2B-2B21-2B3-2B19-2B4-3B17-2B6-3B15-2B8-3B13-2B10-3B11-2B12-2(2B11-)2B13-B11-B14-2B9-2B15-B9-B16-2B2(8-B17-B)7-2B3(17-B8-B)16-2B8-2B15-B10-B15-B10-2B13-2(2B11-)2B13-2B8-3B15-11B19-4B16-18B8-2B16-3B5-2B19-2B4-B20-2B3-2B21-B3-B22-2B2(2-B23-B)-2B23-4B24-2B25-3B23-2B-2B21-2B3-B20-2B4-2B18-2B6-3B15-2B8-3B13-2B10-3B11-2B12-2B10-2(3B11-)2B11-2B13-2B9-2B15-B9-B16-2B2(8-B17-B)7-2B3(17-B8-B)16-2B8-2B15-B10-B14-2B10-2(3B11-)3B9-3B13-3B7-3B15-10B22-B17-18B8-2B16-3B5-2B19-2B4-B21-B3-2B21-2B2-B22-2B2(2-B23-B)-2B23-3B25-2B25-3B23-2B-2B21-2B3-2B19-2B4-3B16-3B6-4B13-3B9-2(3B11-)3B9-3B13-2B9-2B13-2(2B11-)2B12-3B9-3B13-2B9-2(2B15-2B8-)2B15-2B7-2B17-B8-B16-2(2B8-2B15-)2B8-2B14-2B10-2B13-2B2(10-3B)13-3B7-3B15-3B5-3B17-9B40-18B8-2B16-3B5-2B19-2B4-B21-B3-2B21-B3-B22-2B2(2-B23-B)-2B23-4B24-2B25-3B23-2B-2B21-2B3-2B19-2B5-3B14-4B7-4B2(11-3B)9-3B13-2B8-3B14-2B8-3B13-3B9-2B13-2(2B11-)2B12-3B2(10-2B13-2B)9-2B14-3B2(8-2B15-2B)8-3B2(13-2B10-2B)13-2B10-3B11-2B12-3B9-3B13-3B6-3B17-4B-4B19-7B41-18B8-2B16-3B5-2B19-2B4-B2(21-B3-2B)21-2B2(2-B23-B)2-B23-4B24-2B25-3B23-2B-2B21-2B3-3B17-3B5-4B13-4B8-4B9-3B13-3B6-4B15-3B4-4B16-3B4-4B15-3B7-3B13-3B9-2B13-2B11-2B12-2(2B11-)2B12-2B11-3(2B13-2B10-)2B12-3B2(11-2B)12-2B11-2B12-2B10-3B13-3B7-3B15-5B-5B17-8B22-3B43-18B8-2B16-3B5-2B19-2B4-B20-2B4-B21-B3-2B21-2B2-B22-2B2-B23-B2-B2(23-4B)24-3B23-2B-2B21-2B3-3B16-4B6-4B11-4B10-4B6-5B14-11B17-8B19-9B17-11B15-4B5-4B14-2B9-2B13-2B10-2B13-2B11-2B12-2(2B11-)2(2B12-)2(2B11-2B12-)2B10-2B14-2B9-2B14-2B8-3B14-5B2-5B17-9B21-3B70-18B8-2B16-3B5-2B19-B5-B20-2B4-B2(21-B3-2B)21-2B2(2-B23-B)2-B23-4B24-B-B23-2B-2B20-3B3-4B15-4B6-6B7-5B12-6B-6B16-8B22-2B50-7B18-11B15-5B3-4B15-4B5-4B14-3B7-3B13-3B9-2B13-2B11-2B12-2B10-2B14-2B8-3B14-3B7-3B14-4B5-3B16-4B2-5B16-10B20-4B97-18B8-2B16-3B5-2B18-2B5-B20-2B2(4-B21-B)3-2B21-2B2(2-B23-B)2-2(B23-2B-)2B22-2B-3B19-3B3-5B13-4B8-7B3-7B14-9B21-3B104-5B21-7B19-9B17-5B-5B15-5B3-5B14-4B5-4B14-4B4-5B14-5B3-4B16-5B-4B18-9B19-7B21-4B124-18B8-2B16-2B6-2B18-2B5-2B19-2B2(4-B21-B)3-2(2B21-2B2-)2(B23-B2-)B23-2B-2B21-3B2-2B19-3B4-4B12-5B9-15B17-5B159-B25-3B23-5B21-7B19-9B19-7B20-6B22-5B23-3B25-B152-18B8-2B16-2B7-B18-2B5-2B19-2B4-B20-2B2(4-B21-B)3-2B21-2B2(2-B23-B)2-B23-2B-2B21-2B3-2B18-3B5-5B11-5B9-14B263-B25-3B25-B260-18B8-2B16-2B7-2B17-2B5-2B19-B5-B20-2B2(4-B21-B)3-2B21-2B2-2B22-2(B2-B23-)B2-2B21-2B3-3B17-3B5-5B11-4B11-13B578-18B9-2B15-2B7-2B17-2B5-2B19-B5-2B19-2B4-B20-2B4-B21-B4-B2(21-2B2-2B)22-B2-B23-B2-3B19-3B3-3B17-3B6-2(4B11-)13B579-17B9-2B14-3B7-2B16-3B6-B18-2B5-2B19-B5-2B19-2B2(4-B21-B)4-B21-2B2-2B22-B2-B23-B2-3B19-3B4-2B16-3B7-4B10-5B11-13B579-16B10-4B11-3B8-3B15-2B7-2B17-2B6-2B17-2B5-2B18-3B2(4-2B19-2B)4-2B20-2(2B2-2B21-)2B2-3B19-3B4-2B16-3B7-4B11-3B10-16B13-12B555-13B12-2(4B9-)3B13-3B8-2B15-2B7-3B15-2B7-2(2B17-2B6-)2B17-3B2(4-2B19-2B)4-B21-2B3-2B19-3B4-3B15-3B7-3B13-2B11-2B10-3B12-15B14-11B529-11B14-5B5-5B11-3B10-4B10-2B13-2B9-2B14-3B2(8-2B15-2B)7-2B17-2B6-2B17-2B5-2(2B19-2B4-)2B19-2B5-3B15-3B8-2B13-2B11-B12-2B12-3B9-2B14-13B15-11B504-7B17-12B14-4B7-4B11-3B2(11-2B)13-2B10-2B13-2B9-2B15-2B8-B16-2B7-2B17-2B5-2B19-2B4-3B18-2B5-2B17-2B6-3B15-3B8-2B13-2(2B11-)2B12-2B11-B14-2B9-2B15-11B18-7B505-9B16-13B13-4B7-4B12-B12-2B11-2B13-2B9-2B15-B9-2B15-2B7-2(2B17-2B6-)2B17-2B7-2B15-3B7-2B15-2B9-2B13-2(2B11-)2B13-B10-2B14-2B9-2B15-3B5-3B17-9B507-2B22-9B15-6B3-5B13-4B7-4B11-4B9-4B10-B14-2B9-2B15-2B7-2B17-2B6-2B17-2B7-2B15-2B8-2B15-2B9-2B13-2B10-2B13-2(2B11-)2B13-2B9-2B14-2B8-2B16-2B6-3B17-9B533-5B20-9B17-5B-5B13-7B3-6B11-5B7-5B9-3B12-4B8-B16-2B8-2B15-2B8-2B14-3B9-2B13-2B10-2(3B11-)2B10-3B12-3B9-3B13-3B7-3B15-3B4-4B16-4B3-3B18-8B562-3B23-5B20-9B15-7B-6B11-7B4-7B2(9-5B)8-5B9-4B10-5B7-5B10-6B5-5B12-5B5-5B13-4B4-5B14-5B3-4B16-5B-5B17-9B19-6B22-5B617-3B22-6B19-11B15-6B-6B14-6B-5B16-11B17-9B19-2(7B20-)6B22-5B23-3B726-3B23-5B22-4B24-3B24-2B26-B634-
