model
name = dz7hkk8p371q2hwz
size = 24 8 12
scale = 0.05
origin = -y
shell = Outline 0.25
material type = toon, lighting = smooth, deform = 1 1
  colors = A:#3F1C13 B:#341600 C:#941F1F D:#B17500 E:#9F6711
material type = basic, lighting = smooth, roughness = 0, refractionRatio = 1, side = back
  colors = Outline:#000
voxels
--BBBDDDBBBBBBBBBBDDDBBB -BBBBBBBBBBBBBBBBBBBBBB- -BAABAABAABAABAABAABAAB- -BAABAABAABAABAABAABAAB- -BAABAABAABAABAABAABAAB- -BAABAABAABAABAABAABAAB- -BAABAABAABAABAABAABAAB- -BAAEDEBAABAABAABEDEAAB- 
-BBBBBBBBBBBBBBBBBBBBBB- -BAABAABAABAABAABAABAAB- -BAABAABAABAABAABAABAAB- -BAABAABAABAABAABAABAAB- -BAABAABAABAABAABAABAAB- -BAABAABAABAABAABAABAAB- -BAABAABAABAABAABAABAAB- -BBBBBBBBBBBBBBBBBBBBBB- 
-BAAAAAAAAAAAAAAAAAAAAB- -AAAAAAAAAAAAAAAAAAAAAA- -AAAAAAAAAAAAAAAAAAAAAA- -ACCCCCCCCCCCCCCCCCCCCA- -A--------------------A- -A--------------------A- -A--------------------A- -B--------------------B- 
-BAAAAAAAAAAAAAAAAAAAAB- -AAAAAAAAAAAAAAAAAAAAAA- -AAAAAAAAAAAAAAAAAAAAAA- -ACCCCCCCCCCCCCCCCCCCCA- -A--------------------A- -A--------------------A- -A--------------------A- -B--------------------B- 
-BAAAAAAAAAAAAAAAAAAAAB- -BAAAAAAAAAAAAAAAAAAAAB- -BAAAAAAAAAAAAAAAAAAAAB- -BCCCCCCCCCCCCCCCCCCCCB- -B--------------------B- -B--------------------B- -B--------------------B- -B--------------------B- 
-BAAAAAAAAAAAAAAAAAAAAB- -AAAAAAAAAAAAAAAAAAAAAA- -AAAAAAAAAAAAAAAAAAAAAA- -ACCCCCCCCCCCCCCCCCCCCA- DA--------------------AE DA--------------------AE EA--------------------AE -B--------------------B- 
-BAAAAAAAAAAAAAAAAAAAAB- -AAAAAAAAAAAAAAAAAAAAAA- -AAAAAAAAAAAAAAAAAAAAAA- -ACCCCCCCCCCCCCCCCCCCCA- DA--------------------AD -A--------------------A- -A--------------------A- -B--------------------B- 
-BAAAAAAAAAAAAAAAAAAAAB- -BAAAAAAAAAAAAAAAAAAAAB- -BAAAAAAAAAAAAAAAAAAAAB- -BCCCCCCCCCCCCCCCCCCCCB- DB--------------------BD -B--------------------B- -B--------------------B- -B--------------------B- 
-BAAAAAAAAAAAAAAAAAAAAB- -AAAAAAAAAAAAAAAAAAAAAA- -AAAAAAAAAAAAAAAAAAAAAA- -ACCCCCCCCCCCCCCCCCCCCA- EA--------------------AD EA--------------------AD EA--------------------AE -B--------------------B- 
-BAAAAAAAAAAAAAAAAAAAAB- -AAAAAAAAAAAAAAAAAAAAAA- -AAAAAAAAAAAAAAAAAAAAAA- -ACCCCCCCCCCCCCCCCCCCCA- -A--------------------A- -A--------------------A- -A--------------------A- -B--------------------B- 
-BAAAAAAAAAAAAAAAAAAAAB- -BAAAAAAAAAAAAAAAAAAAAB- -BAAAAAAAAAAAAAAAAAAAAB- -BCCCCCCCCCCCCCCCCCCCCB- -B--------------------B- -B--------------------B- -B--------------------B- -B--------------------B- 
-BAAAAAAAAAAAAAAAAAAAAB- -AAAAAAAAAAAAAAAAAAAAAA- -AAAAAAAAAAAAAAAAAAAAAA- -ACCCCCCCCCCCCCCCCCCCCA- -A--------------------A- -A--------------------A- -A--------------------A- -B--------------------B- 
