model
name = jwq25lgjacxuddb9
size = 9 13 7
scale = 0.05
origin = -y
shell = Outline 0.25
material type = toon, lighting = smooth, deform = 1 1
  colors = A:#323220 B:#E6E6EF C:#1D1D11 D:#FFF
material type = basic, lighting = smooth, roughness = 0, refractionRatio = 1, side = back
  colors = Outline:#000
voxels
---AAA--- --------- --------- --------- --------- --------- --------- --------- --------- --------- --------- --------- --------- 
--AAAAA-- --------- --------- --------- --------- --------- --------- --------- --------- --------- --------- --------- --------- 
-AAAAAAA- --------- --------- --------- --------- --------- --------- --------- --------- --------- --------- --------- --------- 
-AAAAAAA- ----A---- ----A---- ----A---- --CCCCC-- -CCBBDCC- CCBDDDBCC CDDDBBBBC CDDBBBDDC ABBBBDBBA AABDDBBAA -AABBBAA- --AAAAA-- 
-AAAAAAA- --------- --------- --------- --------- --------- --------- --------- --------- --------- --------- --------- --------- 
--AAAAA-- --------- --------- --------- --------- --------- --------- --------- --------- --------- --------- --------- --------- 
---AAA--- --------- --------- --------- --------- --------- --------- --------- --------- --------- --------- --------- --------- 
