model
name = nnm6ro53quzoy4ux
size = 13 38 11
scale = 0.05
origin = -y
shell = Outline 0.25
material type = toon, lighting = smooth, deform = 1 1
  colors = A:#1D1D11 B:#3B5222 C:#608344 D:#5A2C20 E:#D1D1BB F:#006D5A G:#258900
material type = basic, lighting = smooth, roughness = 0, refractionRatio = 1, side = back
  colors = Outline:#000
voxels
211-B11-CBC11-B375-8A5-8A58-B287-C10-6A72-2(6A7-)6A5-10A3-2A6-2A19-B12-B11-C91-C12-C91-E51-C12-E25-C22-8A7-4A35-4A8-6A6-2(8A5-)8A4-A7D2A3-A2-C3-B-A6-B3-C12-C36-C22-B15-C23-CB76-EB25-C51-2(C12-)2(B12-)2C21-8A6-6A9-2A11-2A9-6A7-6A6-5AG2(2A5-5AF)2A4-A7D2A3-A2-C2-B2-A8-CB11-B10-3B6-4BC-BC5-2(B2-)2(B9-C2-)B8-2B2-B7-2C3-2B6-CB2-B-C6-B3-B8-E3-2(B12-)B25-B12-C12-B12-2C11-B12-EB11-C51-B12-C9-8A6-6A8-4A9-4A8-6A7-6A6-2(8A5-)8A4-A7D2A3-A-B-2B2-BA2(5-B)3(12-B)22-B34-C8-E7-B11-C12-B6-C5-BC2(11-2B)11-EB24-B12-B2-B9-CB-C9-2B24-2(B12-)C25-B9-8A6-6A8-4A9-4A8-6A7-6A6-2(8A5-)8A4-A7D2A3-A-B3-B-BA4-2B3-B-B6-B3-2(B12-)2B12-B12-2BC10-C-2B9-B2-B3-B5-B2-B6-2C-E2-C6-2(CB)2-EC2-B-2(CB)C2(3-B)CB2CB3-B2-EB-B2CBC2-E2-B2-CB2-E6-2(BC)8-BC-C9-E2-2CB10-2(CB)9-BC-CBE6-2CB-BC6-CBC10-E-CB11-2C10-2BC9-EC-CB20-8A6-6A9-2A11-2A9-6A7-6A6-2(8A5-)8A4-A7D2A3-A8-A121-B2-B5-C6-C12-B10-2(B-)E5-B12-C17-B27-B11-EC24-C11-C-C12-B12-E11-C25-B8-8A7-4A35-4A8-6A6-2(8A5-)8A4-A7D2A3-A2(-B)4-A5-C-B10-C-B9-2B-B7-2CB2-B8-B3-B7-2B2-B3C8-3B10-B-B9-B2-C8-BC-CB7-CE-2B8-B2-B9-B2-E9-C12-B12-C4-E41-E51-C12-C11-B12-BC20-6A72-2(6A7-)6A5-2A6D2A3-2A2-2B2-2A31-3B8-C19-B10-B-C12-E7-E23-C3-B12-B7-B4-B20-C12-E148-3B10-E125-8A5-8A46-CB12-CB89-C197-E4-
