model
name = p5d2gskg28w5qck6
revision = 13
size = 17 30 14
scale = 0.05
origin = -y
shell = Outline 0.25
material type = toon, lighting = smooth, deform = 1 1
  colors = A:#5A2C20 B:#3F1C13 C:#7B552B D:#525046 F:#8E8A7D G:#5E4121 H:#483015 E:#A16F37 I:#1F212A
material type = basic, lighting = smooth, roughness = 0, refractionRatio = 1, side = back
  colors = Outline:#000
voxels
----------------- ----------------- ----------------- ----------------- ----------------- ----------------- ----------------- ----------------- ----------------- ----------------- ----------------- ----------------- ----------------- ----------------- ----------------- ----------------- ----------------- ----------------- ----------------- ----------------- ----------------- ----------------- ----------------- ----------------- ----------------- ----------------- ----------------- ----------------- ----------------- ----------------- 
----------------- ----------------- ----------------- ----------------- ----------------- ----------------- ----------------- ----------------- ----------------- ----------------- ----------------- ----------------- ----------------- ----------------- ----------------- ----------------- ----------------- ----------------- ----------------- ----------------- ----------------- ----------------- ----------------- ----------------- ----------------- ----------------- ----------------- ----------------- ----------------- ----------------- 
--BBB--------BBB- --BBBBBBBBBBBBBB- ---BBBBBBBBBBBB-- ----------------- ----------------- ----------------- ----------------- ----------------- ----------------- --BBBBBBBBBBBB--- ----------------- ----------------- ----------------- ----------------- ----------------- ----------------- ----------------- ----------------- ----------------E ----------------E ---------------CC ---------------CC ---------------CC ---------------CC ---------------CC ---------------CC ----------------E ----------------E ----------------- ----------------- 
--BB----------BB- --BBBBBBBBBBBBBB- --BBBBBBBBBBBBBB- ---BB--------BB-- ---BB--CCCC--BB-- ---BB--C--C--BB-- ---BB--C--C--BB-- ---BB--CCCC--BB-- ---BB--------BB-- --BEAAAAAAAAAA--- ----------------- ----------------- ----------------- ----------------- ----------------- ----------------- ----------------- ----------------E ---------------CC ---------------CC --------------CC- --------------CC- --------------CC- --------------CC- --------------CC- --------------CC- ---------------CC ---------------CC ----------------E ----------------- 
--B------------B- --BBBBBBBBBBBBBB- --BBBBBBBBBBBBBB- ---BAAAAAAAAAAB-- ---BAAAAAAAAAAB-- ---BAAAACCAAAAB-- ---BAAAACCAAAAB-- ---BAAAAAAAAAAB-- ---BAAAAAAAAAAB-- --BAAAAAAAAAAA--- --------DDDD----- ----------------- ----------------- ----------------- ----------------- ----------------- ----------------E ---------------CC --------------CCC --------------CC- ------------CCCC- ------------CCC-- ------------CCC-- ------------CCC-- ------------CCC-- ------------CCCC- --------------CC- ---------------CC ----------------E ----------------- 
----------------- --BBBBBBBBBBBBBB- --BBBBBBBBBBBBBB- ----AAAAAAAAAA--- ----AAAAAAAAAA--- ----AAAAAAAAAA--- ----AAAAAAAAAA--- ----AAAAAAAAAA--- ----AAAAAAAAAA--- --BAAAAAAAAAAA--- -------DDDDDD---- ----------------- ----------------- ----------------- ----------------- ----------------- ----------------E ---------------CC --------------CC- ------------CCCC- ---------CCCCGC-- ---------CCCCGG-- ---------CCCCGG-- ---------CCCCGG-- ---------CCCCGG-- ---------CCCCGC-- ------------CCCC- --------------CC- ---------------CC ----------------E 
----------------- --BBBBBBBBBBBBBB- --BBBBBBBBBBBBBB- ----AAAAAAAAAA--- ----AAAAAAAAAA--- ----AAAAAAAAAA--- ----AAAAAAAAAA--- ----AAAAAAAAAA--- ----AAAAAAAAAA--- --BAAAAAAAAAAA--- ------DDDDDDDD--- ----------------- ----------------- ----------------- ----------------- --FF------------- ----------------E ---------------CC --------------CC- ------------CCC-- -----CCCCCCCCGG-- -----CCCCCCCH---- -----CCCCCHHH---- -----CCCCCHHH---- ------CCCCHHH---- ---------CCCCGG-- ------------CCC-- --------------CC- ---------------CC ----------------E 
----------------- --BBBBBBBBBBBBBB- --BBBBBBBBBBBBBB- ----AAAAAAAAAA--- ----AAAAAAAAAA--- ----AAAAAAAAAA--- -FFFAAAAAAAAAA--- FFFFAAAAAAAAAA--- F---AAAAAAAAAA--- F-BAAAAAAAAAAA--- F-----DDDDDDDD--- F---------------- F--------I------- F--CCC--II------- FFCCCCCEII------- -FFFF------------ --CC------------E --CC-----------CC --CCC---------CC- --CCCC------CCC-- ---CCCCCCCCCCGG-- ---CCCCCCCHHH---- ----CCCCCCH------ -----CCCCCH------ ------CCCCHHH---- ---------CCCCGG-- ------------CCC-- --------------CC- ---------------CC ----------------E 
----------------- --BBBBBBBBBBBBBB- --BBBBBBBBBBBBBB- ----AAAAAAAAAA--- ----AAAAAAAAAA--- ----AAAAAAAAAA--- -FFFAAAAAAAAAA--- FFFFAAAAAAAAAA--- F---AAAAAAAAAA--- F-BAAAAAAAAAAA--- F-----DDDDDDDD--- F---------------- F---------------- F--CCC--II------- FFCCCCCEII------- -FFFF------------ --CC------------E --CC-----------CC --CCC---------CC- --CCCC------CCC-- ---CCCCCCCCCCGG-- ---CCCCCCCHHH---- ----CCCCCCH------ -----CCCCCH------ ------CCCCHHH---- ---------CCCCGG-- ------------CCC-- --------------CC- ---------------CC ----------------E 
----------------- --BBBBBBBBBBBBBB- --BBBBBBBBBBBBBB- ----AAAAAAAAAA--- ----AAAAAAAAAA--- ----AAAAAAAAAA--- ----AAAAAAAAAA--- ----AAAAAAAAAA--- ----AAAAAAAAAA--- --BAAAAAAAAAAAAB- ------DDDDDDDD--- ----------------- ----------------- ----------------- ----------------- --FF------------- ----------------E ---------------CC --------------CC- ------------CCC-- -----CCCCCCCCGG-- -----CCCCCHHH---- -----CCCCCHHH---- -----CCCCCHHH---- ------CCCCCCH---- ---------CCCCGG-- ------------CCC-- --------------CC- ---------------CC ----------------E 
----------------- --BBBBBBBBBBBBBB- --BBBBBBBBBBBBBB- ----AAAAAAAAAA--- ----AAAAAAAAAA--- ----AAAAAAAAAA--- ----AAAAAAAAAA--- ----AAAAAAAAAA--- ----AAAAAAAAAA--- --BAAAAAAAAAAAAB- -------DDDDDD---- ----------------- ----------------- ----------------- ----------------- ----------------- ----------------E ---------------CC --------------CC- ------------CCCC- ---------CCCCGC-- ---------CCCCGG-- ---------CCCCGG-- ---------CCCCGG-- ---------CCCCGG-- ---------CCCCGC-- ------------CCCC- --------------CC- ---------------CC ----------------E 
--B------------B- --BBBBBBBBBBBBBB- --BBBBBBBBBBBBBB- ---BAAAAAAAAAAB-- ---BAAAAAAAAAAB-- ---BAAAAAAAAAAB-- ---BAAAAAAAAAAB-- ---BAAAAAAAAAAB-- ---BAAAAAAAAAAB-- --BAAAAAAAAAAAAB- --------DDDD----- ----------------- ----------------- ----------------- ----------------- ----------------- ----------------E ---------------CC --------------CCC --------------CC- ------------CCCC- ------------CCC-- ------------CCC-- ------------CCC-- ------------CCC-- ------------CCCC- --------------CC- ---------------CC ----------------E ----------------- 
--BB----------BB- --BBBBBBBBBBBBBB- --BBBBBBBBBBBBBB- ---BB--------BB-- ---BB--------BB-- ---BB--------BB-- ---BB--------BB-- ---BB--------BB-- ---BB--------BB-- --BEAAAAAAAAAAEB- ----------------- ----------------- ----------------- ----------------- ----------------- ----------------- ----------------- ----------------E ---------------CC ---------------CC --------------CC- --------------CC- --------------CC- --------------CC- --------------CC- --------------CC- ---------------CC ---------------CC ----------------E ----------------- 
--BBB--------BBB- --BBBBBBBBBBBBBB- --BBBBBBBBBBBBBB- ----------------- ----------------- ----------------- ----------------- ----------------- ----------------- --BBBBBBBBBBBBBB- ----------------- ----------------- ----------------- ----------------- ----------------- ----------------- ----------------- ----------------- ----------------E ----------------E ---------------CC ---------------CC ---------------CC ---------------CC ---------------CC ---------------CC ----------------E ----------------E ----------------- ----------------- 
