model
name = qyyysn4iwr50xw50
size = 4 5 4
scale = 0.05
origin = -y
shell = Outline 0.25
material type = toon, lighting = smooth, deform = 1 1
  colors = A:#085399 B:#808A99 C:#565CE7 D:#00AAE4
material type = basic, lighting = smooth, roughness = 0, refractionRatio = 1, side = back
  colors = Outline:#000
voxels
--BB -BB- -AA- -DC- -AA- 
-BB- -AA- -DC- -AA- -BB- 
BBBB AAAA CCAC AAAA BBBB 
BBBB AAAA DDCD AAAA BBBB 
