model
name = vhnewugrapjgj0mq
revision = 23
size = 36 19 36
scale = 0.05
origin = -y
shell = Outline 0.25
material type = toon, lighting = smooth, deform = 1 1
  colors = A:#6D3011 B:#3F1C13 C:#94591C D:#3F1C11 E:#5A2C20
material type = basic, lighting = smooth, roughness = 0, fade = true, refractionRatio = 1, side = back
  colors = Outline:#000
voxels
14-10D1321-10D602-10B26-10C23-3D10E3D596-16B20-16C18-2(2D7E)2D592-20B16-20C15-D9E2D9ED590-22B14-22C13-D7E2C4D2C7ED23-2(2B34-)2B491-24B12-24C11-D6E2C2A4D2A2C6ED22-3(2B34-)2B454-26B10-26C9-D5E2C3A2D2A2D3A2C5ED57-2(2B34-)2B453-28B8-28C7-D5EC5A2D2A2D5AC5ED56-2(2B34-)2B452-30B6-30C5-D5EC5A3D2A3D5AC5ED55-2(2B34-)2B452-30B6-30C5-D4EC6A2D4A2D6AC4ED55-2(2B34-)2B356-2(6A30-)6A17-32B4-32C3-D4EC6A3D4A2D7AC4ED54-3(2B34-)2B318-2(10A26-)10A15-32B4-32C3-D4EC6A2D14AC4ED54-3(2B34-)2B317-2(12A24-)12A14-32B4-32C3-DE9DA2D2A16DED90-3(2B34-)2B280-2(14A22-)14A12-34B2-34C-D2E9DA2D2A16D2ED89-4(2B34-)2B244-2(14A22-)14A12-34B2-34C-D3E3D5A3D14A3D3ED52-4(4A32-)4A33-2B213-4A26-2(16A20-)16A11-34B2-34C-D3EC3D4A2D7A2D5A3DC3ED51-4(6A30-)6A31-5(4A32-)4A31-6A25-2(16A20-)16A11-34B2-34C-D3ECA3D3A2D7A2D5A2DAC3ED5-2B22-2B10-8B2-6A2-8B10-10B6A10B11-9B6A9B17-4B6A4B24-2B6A2B27-2B4A2B30-4(4A32-)4A31-6A25-2(16A20-)16A11-34B2-34C-D3EC2A3D2A2D8A2D2A3D2AC3ED5-2B22-2B10-8B2-6A2-8B10-10B6A10B11-9B6A9B17-4B6A4B24-2B6A2B27-2B4A2B30-4(4A32-)4A31-6A25-2(16A20-)16A11-34B2-34C-D3EC3A3DA2D8A2DA3D3AC3ED51-4(6A30-)6A31-5(4A32-)4A31-6A25-2(16A20-)16A11-34B2-34C-D3EC4A3D10A3DAD4AC3ED52-2(A-2A32-)2(4A32-)4A33-2B213-4A26-2(16A20-)16A11-34B2-34C-D3EC5A4D9A2D6AC3ED90-B4(34-2B)244-2(14A22-)14A12-34B2-34C-D3EC7A3D5A2DA2D6AC3ED90-B3(34-2B)280-2(14A22-)14A12-34B2-34C-D4EC4AD2A3D3A3D2A2D4AC4ED53-3(2B34-)2B317-2(12A24-)12A14-32B4-32C3-D3EC4A2D2AD3A3D3A2D4AC3ED54-3(2B34-)2B318-2(10A26-)10A15-32B4-32C3-D4EC2A3D4A4D-3A3D2AC4ED54-2(2B34-)2B356-2(6A30-)6A17-32B4-32C3-D4EC2A2D4A4DAD4A2D2AC4ED54-2(2B34-)2B452-30B6-30C5-D4ECA2D3A3D2A3D3A2DAC4ED55-2(2B34-)2B452-30B6-30C5-D5E2D2A4D4A4D2A2D5ED55-2(2B34-)2B453-28B8-28C7-D4E2DA4D7A3DA2D4ED20-3(2B34-)2B454-26B10-26C9-D3E5D10A5D3ED21-2(2B34-)2B491-24B12-24C11-D2E3D2E2C6A2CE4D2ED588-22B14-22C13-D8E6C8ED590-20B16-20C15-D20ED593-16B20-16C18-2D16E2D601-6B30-6C23-2D5-6E3D10-
