model
name = wemwv9qft4bjen1s
size = 30 38 9
scale = 0.05
origin = -y
shell = Outline 0.25
material type = toon, lighting = smooth, deform = 1 1
  colors = A:#5A2C20 B:#C8A44D C:#4D2211 D:#BA953B E:#6D3011 F:#3F1C13 G:#B17500 H:#FE01FE
material type = basic, lighting = smooth, roughness = 0, refractionRatio = 1, side = back
  colors = Outline:#000
voxels
4(26A-2A-)2(26A-3F)15(26A-2A-)3A20-3A-2A-3A-18G8(-3A-2A-3A-G16EG)-3A-2A-3A-18G-3A-3F3A20-3A-3F5(26A-2A-)4(26AC2A-)2(26A4F)15(26AC2A-)10(3A20C3AC2A-)2(3A20C3A4F)2(26AC2A-)6A2-18A2(C2A-26A)C2A29-A2-25B2GA2-27B2(A2-2B24-B)2(2F-2B24-B)2(A2-2B24-B)21(C2-2B24-B)2(A2-2B24-B)2(2F-2B24-B)2(A2-2B24-B)A2-25B2G2(A29-)A2-26DGA2-25D2B2(A2-2D24-B)AF-2D22-H-BAF-2(2D24-BA2-)21(2D24-BC2-)2(2D24-BA2-)2(2D24-BAF-)2D24-BA2-2D3-H20-BA2-2D24-BA2-26DG2(A29-)A2-26BGA2-27B2(A2-2B24-B)2(AF-2B24-B)2(A2-2B24-B)21(C2-2B24-B)2(A2-2B24-B)2(AF-2B24-B)2(A2-2B24-B)A2-26BG2(A29-)A2-26DGA2-25D2B2(A2-2D24-B)2(AF-2D24-B)2(A2-2D24-B)21(C2-2D24-B)2(A2-2D24-B)2(AF-2D24-B)2(A2-2D24-B)A2-26DG2(A29-)A2-25B2GA2-27B2(A2-2B24-B)2(AF-2B24-B)2(A2-2B24-B)21(C2-2B24-B)2(A2-2B24-B)2(AF-2B24-B)2(A2-2B24-B)A2-25B2GA29-A4(-26AC2A)-2(26A4F)25(26AC2A-)2(26A4F)5(26AC2A-)4(26A-2A-)2(26A-3F)25(26A-2A-)2(26A-3F)5(26A-2A-)
