model
name = zfzkhfnimozoho61
size = 10 5 12
scale = 0.05
origin = -y
shell = Outline 0.25
material type = toon, lighting = smooth, deform = 1 1
  colors = A:#7B3E1E B:#5A2C20 C:#985433 D:#785945
material type = basic, lighting = smooth, roughness = 0, refractionRatio = 1, side = back
  colors = Outline:#000
voxels
-CCCCCCCCC CCCCCCCCCC C--DDDD--C C-DD--DD-C C--------C 
AAAAAAAAAA AAAAAAAAAA ABBBBBBBBA ABBBBBBBBA ABBBBBBBBA 
AAAAAAAAAA ABBBBBBBBA A--------A A--------A A--------A 
AAAAAAAAAA ABBBBBBBBA A--------A A--------A A--------A 
AAAAAAAAAA ABBBBBBBBA A--------A A--------A A--------A 
AAAAAAAAAA ABBBBBBBBA A--------A A--------A A--------A 
AAAAAAAAAA ABBBBBBBBA A--------A A--------A A--------A 
AAAAAAAAAA ABBBBBBBBA A--------A A--------A A--------A 
AAAAAAAAAA ABBBBBBBBA A--------A A--------A A--------A 
AAAAAAAAAA ABBBBBBBBA A--------A A--------A A--------A 
AAAAAAAAAA ABBBBBBBBA A--------A A--------A A--------A 
AAAAAAAAAA AAAAAAAAAA AAAAAAAAAA AAAAAAAAAA A--------A 
